<?xml version="1.0" encoding="utf-8"?>
<mujoco model="base_cabinet_600">
  <compiler angle="radian" meshdir="assets" texturedir="assets" autolimits="true"/>
  <asset>
    <texture type="2d" name="drawer_600_full" file="drawer_600_full.png"/>
    <texture type="2d" name="drawer_600_half" file="drawer_600_half.png"/>
    <texture type="2d" name="drawer_600_quarter" file="drawer_600_quarter.png"/>
    <texture type="2d" name="counter" file="counter.png"/>
    <texture type="2d" name="hob" file="hob.png"/>
    <texture type="2d" name="handle" file="handle.png"/>
    <material name="cabinet" shininess="0.1"/>
    <material name="back" shininess="0.1"/>
    <material name="counter" shininess="0.1" texture="counter" texuniform="true" texrepeat="2 2"/>
    <material name="hob" texture="hob"/>
    <material name="drawer_600_full" shininess="0.1" texture="drawer_600_full"/>
    <material name="drawer_600_half" shininess="0.1" texture="drawer_600_half"/>
    <material name="drawer_600_quarter" shininess="0.1" texture="drawer_600_quarter"/>
    <material name="handle" rgba="0.5 0.5 0.5 1" texture="handle"/>
    <mesh file="drawer_600_full.obj"/>
    <mesh file="drawer_600_half.obj"/>
    <mesh file="drawer_600_quarter.obj"/>
    <mesh file="drawer_handle.obj"/>
  </asset>
  <default>
    <default class="base_cabinet_600">
      <geom density="10" solimp="0.998 0.998 0.001" solref="0.004 1"/>
      <joint solimplimit="0.998 0.998 0.001" solreflimit="0.004 1"/>
      <default class="visual">
        <geom contype="0" conaffinity="0"/>
      </default>
      <default class="collision">
        <geom mass="0" group="3"/>
      </default>
      <site size="0.001" rgba="0.5 0.5 0.5 0.3" group="4"/>
    </default>
  </default>
  <worldbody>
    <body name="base_cabinet_600" childclass="base_cabinet_600">
      <body name="walls">
        <geom pos="0 -0.048 0.47" size="0.298 0.35 0.002" type="box" material="back" euler="1.5708 0 0"/>
        <geom pos="0.292 -0.3 0.47" size="0.25 0.35 0.008" type="box" material="cabinet" euler="1.5708 1.5708 0"/>
        <geom pos="-0.292 -0.3 0.47" size="0.25 0.35 0.008" type="box" material="cabinet" euler="1.5708 1.5708 0"/>
        <body name="shelf_bottom">
          <geom pos="0 -0.3 0.128" size="0.25 0.284 0.008" type="box" material="cabinet" euler="0 0 1.5708"/>
        </body>
        <geom pos="0 -0.51 0.812" size="0.04 0.284 0.008" type="box" material="cabinet" euler="0 0 1.5708"/>
        <geom pos="0 -0.298 0.06" size="0.3 0.06 0.248" type="box" material="cabinet" euler="1.5708 0 0"/>
      </body>
      <body name="counter" pos="0 -0.2985 0.84">
        <geom class="visual" size="0.298 0.298 0.019" type="box" material="counter" euler="0 0 1.5708"/>
        <geom class="visual" pos="0 -0.299 0" size="0.3 0.019 0.001" type="box" material="counter" euler="1.5708 0 0"/>
        <geom class="visual" pos="0 0.299 0" size="0.3 0.019 0.001" type="box" material="counter" euler="1.5708 0 0"/>
        <geom class="visual" pos="0.299 0 0" size="0.3 0.019 0.001" type="box" material="counter" euler="1.5708 1.5708 0"/>
        <geom class="visual" pos="-0.299 0 0" size="0.3 0.019 0.001" type="box" material="counter" euler="1.5708 1.5708 0"/>
        <geom class="collision" size="0.3 0.3 0.019" type="box" euler="0 0 1.5708" solimp="0.95 0.98 0.001"/>
      </body>
      <body name="hob" pos="0 -0.3 0.85">
        <geom size="0.29 0.257 0.02" type="box" material="hob" solimp="0.95 0.98 0.001"/>
        <site name="hob_site_1" pos="-0.155 -0.08 0.02"/>
        <site name="hob_site_2" pos="-0.155 0.142 0.02"/>
        <site name="hob_site_3" pos="0.122 0.122 0.02"/>
        <site name="hob_site_4" pos="0.168 -0.096 0.02"/>
      </body>
      <body name="shelf" pos="0 -0.2985 0.474">
        <geom size="0.25 0.284 0.008" type="box" material="cabinet" euler="0 0 1.5708"/>
      </body>
      <body name="panel" pos="0 -0.56 0.474">
        <geom pos="0 0 0" type="mesh" mesh="drawer_600_full" material="drawer_600_full" euler="1.5708 0 0"/>
      </body>
      <body name="door_right" pos="-0.29 -0.56 0.474">
        <joint pos="0 -0.008 0" name="door_right" type="hinge" axis="0 0 -1" damping="0.2" range="0 1.5708"/>
        <geom pos="0.29 -0.004 0" type="mesh" mesh="drawer_600_full" material="drawer_600_full" euler="1.5708 0 0"/>
        <body pos="0.56 0 0.2" euler="-3.1416 1.5708 0">
          <geom type="mesh" mesh="drawer_handle" material="handle" class="visual" euler="1.5708 0 0"/>
          <geom pos="0 0.027 0" size="0.06 0.0032 0.006" type="box" class="collision"/>
          <geom pos="-0.0425 0.015 0" size="0.006 0.015 0.006" type="box" class="collision"/>
          <geom pos="0.0425 0.015 0" size="0.006 0.015 0.006" type="box" class="collision"/>
        </body>
      </body>
      <body name="door_left" pos="0.29 -0.56 0.474">
        <joint pos="0 -0.008 0" name="door_left" type="hinge" axis="0 0 1" damping="0.2" range="0 1.5708"/>
        <geom pos="-0.29 -0.004 0" type="mesh" mesh="drawer_600_full" material="drawer_600_full" euler="1.5708 0 0"/>
        <body pos="-0.56 0 0.2" euler="-3.1416 1.5708 0">
          <geom type="mesh" mesh="drawer_handle" material="handle" class="visual" euler="1.5708 0 0"/>
          <geom pos="0 0.027 0" size="0.06 0.0032 0.006" type="box" class="collision"/>
          <geom pos="-0.0425 0.015 0" size="0.006 0.015 0.006" type="box" class="collision"/>
          <geom pos="0.0425 0.015 0" size="0.006 0.015 0.006" type="box" class="collision"/>
        </body>
      </body>
      <body name="drawer_big_1" pos="0 -0.325 0.148">
        <joint name="drawer_big_1" type="slide" axis="0 -1 0" damping="10" range="0 0.38" frictionloss="1"/>
        <geom pos="0 0 0" size="0.223 0.269 0.002" type="box" material="cabinet" euler="0 0 1.5708"/>
        <geom pos="-0.263 0 0.149" size="0.225 0.147 0.008" type="box" material="cabinet" euler="1.5708 1.5708 0"/>
        <geom pos="0.263 0 0.149" size="0.225 0.147 0.008" type="box" material="cabinet" euler="1.5708 1.5708 0"/>
        <geom pos="0 0.217 0.149" size="0.255 0.147 0.008" type="box" material="cabinet" euler="1.5708 0 0"/>
        <geom pos="0 -0.217 0.1475" size="0.255 0.147 0.008" type="box" material="cabinet" euler="1.5708 0 0"/>
        <geom pos="0 -0.236 0.1475" type="mesh" mesh="drawer_600_half" material="drawer_600_half" euler="1.5708 0 0"/>
        <body pos="0 -0.236 0.290" euler="-3.1416 0 0">
          <geom type="mesh" mesh="drawer_handle" material="handle" class="visual" euler="1.5708 0 0"/>
          <geom pos="0 0.027 0" size="0.06 0.0032 0.006" type="box" class="collision"/>
          <geom pos="-0.0425 0.015 0" size="0.006 0.015 0.006" type="box" class="collision"/>
          <geom pos="0.0425 0.015 0" size="0.006 0.015 0.006" type="box" class="collision"/>
        </body>
        <site name="drawer_big_1" pos="0 0 0.002"/>
      </body>
      <body name="drawer_big_2" pos="0 -0.325 0.495">
        <joint name="drawer_big_2" type="slide" axis="0 -1 0" damping="10" range="0 0.38" frictionloss="1"/>
        <geom pos="0 0 0" size="0.223 0.269 0.002" type="box" material="cabinet" euler="0 0 1.5708"/>
        <geom pos="-0.263 0 0.149" size="0.225 0.147 0.008" type="box" material="cabinet" euler="1.5708 1.5708 0"/>
        <geom pos="0.263 0 0.149" size="0.225 0.147 0.008" type="box" material="cabinet" euler="1.5708 1.5708 0"/>
        <geom pos="0 0.217 0.149" size="0.255 0.147 0.008" type="box" material="cabinet" euler="1.5708 0 0"/>
        <geom pos="0 -0.217 0.1475" size="0.255 0.147 0.008" type="box" material="cabinet" euler="1.5708 0 0"/>
        <geom pos="0 -0.236 0.1475" type="mesh" mesh="drawer_600_half" material="drawer_600_half" euler="1.5708 0 0"/>
        <body pos="0 -0.236 0.290" euler="-3.1416 0 0">
          <geom type="mesh" mesh="drawer_handle" material="handle" class="visual" euler="1.5708 0 0"/>
          <geom pos="0 0.027 0" size="0.06 0.0032 0.006" type="box" class="collision"/>
          <geom pos="-0.0425 0.015 0" size="0.006 0.015 0.006" type="box" class="collision"/>
          <geom pos="0.0425 0.015 0" size="0.006 0.015 0.006" type="box" class="collision"/>
        </body>
        <site name="drawer_big_2" pos="0 0 0.002"/>
      </body>
      <body name="drawer_small_1" pos="0 -0.325 0.148">
        <joint name="drawer_small_1" type="slide" axis="0 -1 0" damping="10" range="0 0.38" frictionloss="1"/>
        <geom pos="0 0 0" size="0.223 0.269 0.002" type="box" material="cabinet" euler="0 0 1.5708"/>
        <geom pos="-0.263 0 0.0605" size="0.225 0.059 0.008" type="box" material="cabinet" euler="1.5708 1.5708 0"/>
        <geom pos="0.263 0 0.0605" size="0.225 0.059 0.008" type="box" material="cabinet" euler="1.5708 1.5708 0"/>
        <geom pos="0 0.217 0.0605" size="0.255 0.059 0.008" type="box" material="cabinet" euler="1.5708 0 0"/>
        <geom pos="0 -0.217 0.0605" size="0.255 0.059 0.008" type="box" material="cabinet" euler="1.5708 0 0"/>
        <geom pos="0 -0.236 0.0623" type="mesh" mesh="drawer_600_quarter" material="drawer_600_quarter" euler="1.5708 0 0"/>
        <body pos="0 -0.236 0.0623" euler="-3.1416 0 0">
          <geom type="mesh" mesh="drawer_handle" material="handle" class="visual" euler="1.5708 0 0"/>
          <geom pos="0 0.027 0" size="0.06 0.0032 0.006" type="box" class="collision"/>
          <geom pos="-0.0425 0.015 0" size="0.006 0.015 0.006" type="box" class="collision"/>
          <geom pos="0.0425 0.015 0" size="0.006 0.015 0.006" type="box" class="collision"/>
        </body>
        <site name="drawer_small_1" pos="0 0 0.002"/>
      </body>
      <body name="drawer_small_2" pos="0 -0.325 0.32">
        <joint name="drawer_small_2" type="slide" axis="0 -1 0" damping="10" range="0 0.38" frictionloss="1"/>
        <geom pos="0 0 0" size="0.223 0.269 0.002" type="box" material="cabinet" euler="0 0 1.5708"/>
        <geom pos="-0.263 0 0.0605" size="0.225 0.059 0.008" type="box" material="cabinet" euler="1.5708 1.5708 0"/>
        <geom pos="0.263 0 0.0605" size="0.225 0.059 0.008" type="box" material="cabinet" euler="1.5708 1.5708 0"/>
        <geom pos="0 0.217 0.0605" size="0.255 0.059 0.008" type="box" material="cabinet" euler="1.5708 0 0"/>
        <geom pos="0 -0.217 0.0605" size="0.255 0.059 0.008" type="box" material="cabinet" euler="1.5708 0 0"/>
        <geom pos="0 -0.236 0.0623" type="mesh" mesh="drawer_600_quarter" material="drawer_600_quarter" euler="1.5708 0 0"/>
        <body pos="0 -0.236 0.0623" euler="-3.1416 0 0">
          <geom type="mesh" mesh="drawer_handle" material="handle" class="visual" euler="1.5708 0 0"/>
          <geom pos="0 0.027 0" size="0.06 0.0032 0.006" type="box" class="collision"/>
          <geom pos="-0.0425 0.015 0" size="0.006 0.015 0.006" type="box" class="collision"/>
          <geom pos="0.0425 0.015 0" size="0.006 0.015 0.006" type="box" class="collision"/>
        </body>
        <site name="drawer_small_2" pos="0 0 0.002"/>
      </body>
      <body name="drawer_small_3" pos="0 -0.325 0.492">
        <joint name="drawer_small_3" type="slide" axis="0 -1 0" damping="10" range="0 0.38" frictionloss="1"/>
        <geom pos="0 0 0" size="0.223 0.269 0.002" type="box" material="cabinet" euler="0 0 1.5708"/>
        <geom pos="-0.263 0 0.0605" size="0.225 0.059 0.008" type="box" material="cabinet" euler="1.5708 1.5708 0"/>
        <geom pos="0.263 0 0.0605" size="0.225 0.059 0.008" type="box" material="cabinet" euler="1.5708 1.5708 0"/>
        <geom pos="0 0.217 0.0605" size="0.255 0.059 0.008" type="box" material="cabinet" euler="1.5708 0 0"/>
        <geom pos="0 -0.217 0.0605" size="0.255 0.059 0.008" type="box" material="cabinet" euler="1.5708 0 0"/>
        <geom pos="0 -0.236 0.0623" type="mesh" mesh="drawer_600_quarter" material="drawer_600_quarter" euler="1.5708 0 0"/>
        <body pos="0 -0.236 0.0623" euler="-3.1416 0 0">
          <geom type="mesh" mesh="drawer_handle" material="handle" class="visual" euler="1.5708 0 0"/>
          <geom pos="0 0.027 0" size="0.06 0.0032 0.006" type="box" class="collision"/>
          <geom pos="-0.0425 0.015 0" size="0.006 0.015 0.006" type="box" class="collision"/>
          <geom pos="0.0425 0.015 0" size="0.006 0.015 0.006" type="box" class="collision"/>
        </body>
        <site name="drawer_small_3" pos="0 0 0.002"/>
      </body>
      <body name="drawer_small_4" pos="0 -0.325 0.664">
        <joint name="drawer_small_4" type="slide" axis="0 -1 0" damping="10" range="0 0.38" frictionloss="1"/>
        <geom pos="0 0 0" size="0.223 0.269 0.002" type="box" material="cabinet" euler="0 0 1.5708"/>
        <geom pos="-0.263 0 0.0605" size="0.225 0.059 0.008" type="box" material="cabinet" euler="1.5708 1.5708 0"/>
        <geom pos="0.263 0 0.0605" size="0.225 0.059 0.008" type="box" material="cabinet" euler="1.5708 1.5708 0"/>
        <geom pos="0 0.217 0.0605" size="0.255 0.059 0.008" type="box" material="cabinet" euler="1.5708 0 0"/>
        <geom pos="0 -0.217 0.0605" size="0.255 0.059 0.008" type="box" material="cabinet" euler="1.5708 0 0"/>
        <geom pos="0 -0.236 0.0623" type="mesh" mesh="drawer_600_quarter" material="drawer_600_quarter" euler="1.5708 0 0"/>
        <body pos="0 -0.236 0.0623" euler="-3.1416 0 0">
          <geom type="mesh" mesh="drawer_handle" material="handle" class="visual" euler="1.5708 0 0"/>
          <geom pos="0 0.027 0" size="0.06 0.0032 0.006" type="box" class="collision"/>
          <geom pos="-0.0425 0.015 0" size="0.006 0.015 0.006" type="box" class="collision"/>
          <geom pos="0.0425 0.015 0" size="0.006 0.015 0.006" type="box" class="collision"/>
        </body>
        <site name="drawer_small_4" pos="0 0 0.002"/>
      </body>
    </body>
  </worldbody>
</mujoco>
